<?xml version="1.0"?>
<robot xmlns:xacro="http://www.ros.org/wiki/xacro" name="goddard">
    <link name="base_link" />

    <link name="body">
        <inertial>
            <mass value="1" />
            <inertia ixx="0.1" ixy="0" ixz="0" iyy="0.1"
                iyz="0" izz="0.1" />
        </inertial>
        <collision>
            <geometry>
                <mesh filename="file://$(find goddard_description)/meshes/body.stl"
                    scale="0.001 0.001 0.001" />
            </geometry>
        </collision>
        <visual>
            <geometry>
                <mesh filename="file://$(find goddard_description)/meshes/body.stl"
                    scale="0.001 0.001 0.001" />
            </geometry>
        </visual>
    </link>

    <joint name="body_to_base_link" type="fixed">
        <parent link="base_link" />
        <child link="body" />
        <origin xyz="0 0 0.1226" rpy="0 0 0" />
    </joint>

    <!-- Front Left Components  -->

    <link name="front_left_hip">
        <inertial>
            <mass value="1" />
            <inertia ixx="0.1" ixy="0" ixz="0" iyy="0.1"
                iyz="0" izz="0.1" />
        </inertial>
        <collision>
            <geometry>
                <mesh filename="file://$(find goddard_description)/meshes/hip.stl"
                    scale="0.001 0.001 0.001" />
            </geometry>
        </collision>
        <visual>
            <geometry>
                <mesh filename="file://$(find goddard_description)/meshes/hip.stl"
                    scale="0.001 0.001 0.001" />
            </geometry>
        </visual>
    </link>

    <joint name="front_left_hip_to_body" type="revolute">
        <parent link="body" />
        <child link="front_left_hip" />
        <origin xyz="0.07900 0.05713 0.003000" rpy="0 0 0" />
        <axis xyz="1 0 0" />
        <limit lower="-1.571" upper="1.571" effort="1000" velocity="0.5" />

    </joint>

    <link name="front_left_femur">
        <inertial>
            <mass value="1" />
            <inertia ixx="0.1" ixy="0" ixz="0" iyy="0.1"
                iyz="0" izz="0.1" />
        </inertial>
        <collision>
            <geometry>
                <mesh filename="file://$(find goddard_description)/meshes/femur.stl"
                    scale="0.001 0.001 0.001" />
            </geometry>
            <origin xyz="-0.0246 0 -0.02835" rpy="0 0 0" />
        </collision>
        <visual>
            <geometry>
                <mesh filename="file://$(find goddard_description)/meshes/femur.stl"
                    scale="0.001 0.001 0.001" />
            </geometry>
            <origin xyz="-0.0246 0 -0.02835" rpy="0 0 0" />
        </visual>
    </link>

    <joint name="front_left_femur_to_front_left_hip" type="revolute">
        <parent link="front_left_hip" />
        <child link="front_left_femur" />
        <origin xyz="0 0.03558 -0.00469" rpy="0 0 0" />
        <axis xyz="0 -1 0" />
        <limit lower="-1.571" upper="1.571" effort="1000" velocity="0.5" />
    </joint>


    <link name="front_left_tibia">
        <inertial>
            <mass value="1" />
            <inertia ixx="0.1" ixy="0" ixz="0" iyy="0.1"
                iyz="0" izz="0.1" />
        </inertial>
        <collision>
            <geometry>
                <mesh filename="file://$(find goddard_description)/meshes/tibia.stl"
                    scale="0.001 0.001 0.001" />
            </geometry>
            <origin xyz="0.01861 0 -0.02100" rpy="0 0 0" />
        </collision>
        <visual>
            <geometry>
                <mesh filename="file://$(find goddard_description)/meshes/tibia.stl"
                    scale="0.001 0.001 0.001" />
            </geometry>
            <origin xyz="0.01861 0 -0.02100" rpy="0 0 0" />
        </visual>
    </link>

    <joint name="front_left_tibia_to_front_left_femur" type="revolute">
        <parent link="front_left_femur" />
        <child link="front_left_tibia" />
        <origin xyz="-0.05367 0 -0.05261" rpy="0 0 0" />
        <axis xyz="0 -1 0" />
        <limit lower="-1.571" upper="1.571" effort="1000" velocity="0.5" />
    </joint>

    <!-- Front Right Components -->

    <link name="front_right_hip">
        <inertial>
            <mass value="1" />
            <inertia ixx="0.1" ixy="0" ixz="0" iyy="0.1"
                iyz="0" izz="0.1" />
        </inertial>
        <collision>
            <geometry>
                <mesh filename="file://$(find goddard_description)/meshes/hip.stl"
                    scale="0.001 0.001 0.001" />
            </geometry>
            <origin xyz="0 0 0" rpy="0 0 3.142" />
        </collision>
        <visual>
            <geometry>
                <mesh filename="file://$(find goddard_description)/meshes/hip.stl"
                    scale="0.001 0.001 0.001" />
            </geometry>
            <origin xyz="0 0 0" rpy="0 0 3.142" />
        </visual>
    </link>

    <joint name="front_right_hip_to_body" type="revolute">
        <parent link="body" />
        <child link="front_right_hip" />
        <origin xyz="0.07900 -0.05713 0.003000" rpy="0 0 0" />
        <axis xyz="-1 0 0" />
        <limit lower="-1.571" upper="1.571" effort="1000" velocity="0.5" />
    </joint>

    <link name="front_right_femur">
        <inertial>
            <mass value="1" />
            <inertia ixx="0.1" ixy="0" ixz="0" iyy="0.1"
                iyz="0" izz="0.1" />
        </inertial>
        <collision>
            <geometry>
                <mesh filename="file://$(find goddard_description)/meshes/femur.stl"
                    scale="0.001 0.001 0.001" />
            </geometry>
            <origin xyz="-0.0246 0 -0.02835" rpy="0 0 0" />
        </collision>
        <visual>
            <geometry>
                <mesh filename="file://$(find goddard_description)/meshes/femur.stl"
                    scale="0.001 0.001 0.001" />
            </geometry>
            <origin xyz="-0.0246 0 -0.02835" rpy="0 0 0" />
        </visual>
    </link>

    <joint name="front_right_femur_to_front_right_hip" type="revolute">
        <parent link="front_right_hip" />
        <child link="front_right_femur" />
        <origin xyz="0 -0.03558 -0.00469" rpy="0 0 0" />
        <axis xyz="0 -1 0" />
        <limit lower="-1.571" upper="1.571" effort="1000" velocity="0.5" />
    </joint>

    <link name="front_right_tibia">
        <inertial>
            <mass value="1" />
            <inertia ixx="0.1" ixy="0" ixz="0" iyy="0.1"
                iyz="0" izz="0.1" />
        </inertial>
        <collision>
            <geometry>
                <mesh filename="file://$(find goddard_description)/meshes/tibia.stl"
                    scale="0.001 0.001 0.001" />
            </geometry>
            <origin xyz="0.01861 0 -0.02100" rpy="0 0 0" />
        </collision>
        <visual>
            <geometry>
                <mesh filename="file://$(find goddard_description)/meshes/tibia.stl"
                    scale="0.001 0.001 0.001" />
            </geometry>
            <origin xyz="0.01861 0 -0.02100" rpy="0 0 0" />
        </visual>
    </link>

    <joint name="front_right_tibia_to_front_right_femur" type="revolute">
        <parent link="front_right_femur" />
        <child link="front_right_tibia" />
        <origin xyz="-0.05367 0 -0.05261" rpy="0 0 0" />
        <axis xyz="0 -1 0" />
        <limit lower="-1.571" upper="1.571" effort="1000" velocity="0.5" />
    </joint>


    <!-- Back Left Components -->

    <link name="back_left_hip">
        <inertial>
            <mass value="1" />
            <inertia ixx="0.1" ixy="0" ixz="0" iyy="0.1"
                iyz="0" izz="0.1" />
        </inertial>
        <collision>
            <geometry>
                <mesh filename="file://$(find goddard_description)/meshes/hip.stl"
                    scale="0.001 0.001 0.001" />
            </geometry>
            <origin xyz="0 0 0" rpy="0 0 3.142" />
        </collision>
        <visual>
            <geometry>
                <mesh filename="file://$(find goddard_description)/meshes/hip.stl"
                    scale="0.001 0.001 0.001" />
            </geometry>
            <origin xyz="0 0 0" rpy="0 0 3.142" />
        </visual>
    </link>

    <joint name="back_left_hip_to_body" type="revolute">
        <parent link="body" />
        <child link="back_left_hip" />
        <origin xyz="-0.07900 0.05713 0.003000" rpy="0 0 0" />
        <axis xyz="1 0 0" />
        <limit lower="-1.571" upper="1.571" effort="1000" velocity="0.5" />
    </joint>

    <link name="back_left_femur">
        <inertial>
            <mass value="1" />
            <inertia ixx="0.1" ixy="0" ixz="0" iyy="0.1"
                iyz="0" izz="0.1" />
        </inertial>
        <collision>
            <geometry>
                <mesh filename="file://$(find goddard_description)/meshes/femur.stl"
                    scale="0.001 0.001 0.001" />
            </geometry>
            <origin xyz="-0.0246 0 -0.02835" rpy="0 0 0" />
        </collision>
        <visual>
            <geometry>
                <mesh filename="file://$(find goddard_description)/meshes/femur.stl"
                    scale="0.001 0.001 0.001" />
            </geometry>
            <origin xyz="-0.0246 0 -0.02835" rpy="0 0 0" />
        </visual>
    </link>

    <joint name="back_left_femur_to_back_left_hip" type="revolute">
        <parent link="back_left_hip" />
        <child link="back_left_femur" />
        <origin xyz="0 0.03558 -0.00469" rpy="0 0 0" />
        <axis xyz="0 -1 0" />
        <limit lower="-1.571" upper="1.571" effort="1000" velocity="0.5" />
    </joint>

    <link name="back_left_tibia">
        <inertial>
            <mass value="1" />
            <inertia ixx="0.1" ixy="0" ixz="0" iyy="0.1"
                iyz="0" izz="0.1" />
        </inertial>
        <collision>
            <geometry>
                <mesh filename="file://$(find goddard_description)/meshes/tibia.stl"
                    scale="0.001 0.001 0.001" />
            </geometry>
            <origin xyz="0.01861 0 -0.02100" rpy="0 0 0" />
        </collision>
        <visual>
            <geometry>
                <mesh filename="file://$(find goddard_description)/meshes/tibia.stl"
                    scale="0.001 0.001 0.001" />
            </geometry>
            <origin xyz="0.01861 0 -0.02100" rpy="0 0 0" />
        </visual>
    </link>

    <joint name="back_left_tibia_to_back_left_femur" type="revolute">
        <parent link="back_left_femur" />
        <child link="back_left_tibia" />
        <origin xyz="-0.05367 0 -0.05261" rpy="0 0 0" />
        <axis xyz="0 -1 0" />
        <limit lower="-1.571" upper="1.571" effort="1000" velocity="0.5" />
    </joint>

    <!-- Back Right Components -->

    <link name="back_right_hip">
        <inertial>
            <mass value="1" />
            <inertia ixx="0.1" ixy="0" ixz="0" iyy="0.1"
                iyz="0" izz="0.1" />
        </inertial>
        <collision>
            <geometry>
                <mesh filename="file://$(find goddard_description)/meshes/hip.stl"
                    scale="0.001 0.001 0.001" />
            </geometry>
            <origin xyz="0 0 0" rpy="0 0 3.142" />
        </collision>
        <visual>
            <geometry>
                <mesh filename="file://$(find goddard_description)/meshes/hip.stl"
                    scale="0.001 0.001 0.001" />
            </geometry>
            <origin xyz="0 0 0" rpy="0 0 3.142" />
        </visual>
    </link>

    <joint name="back_right_hip_to_body" type="revolute">
        <parent link="body" />
        <child link="back_right_hip" />
        <origin xyz="-0.07900 -0.05713 0.003000" rpy="0 0 0" />
        <axis xyz="-1 0 0" />
        <limit lower="-1.571" upper="1.571" effort="1000" velocity="0.5" />
    </joint>

    <link name="back_right_femur">
        <inertial>
            <mass value="1" />
            <inertia ixx="0.1" ixy="0" ixz="0" iyy="0.1"
                iyz="0" izz="0.1" />
        </inertial>
        <collision>
            <geometry>
                <mesh filename="file://$(find goddard_description)/meshes/femur.stl"
                    scale="0.001 0.001 0.001" />
            </geometry>
            <origin xyz="-0.0246 0 -0.02835" rpy="0 0 0" />
        </collision>
        <visual>
            <geometry>
                <mesh filename="file://$(find goddard_description)/meshes/femur.stl"
                    scale="0.001 0.001 0.001" />
            </geometry>
            <origin xyz="-0.0246 0 -0.02835" rpy="0 0 0" />
        </visual>
    </link>

    <joint name="back_right_femur_to_back_right_hip" type="revolute">
        <parent link="back_right_hip" />
        <child link="back_right_femur" />
        <origin xyz="0 -0.03558 -0.00469" rpy="0 0 0" />
        <axis xyz="0 -1 0" />
        <limit lower="-1.571" upper="1.571" effort="1000" velocity="0.5" />
    </joint>

    <link name="back_right_tibia">
        <inertial>
            <mass value="1" />
            <inertia ixx="0.1" ixy="0" ixz="0" iyy="0.1"
                iyz="0" izz="0.1" />
        </inertial>
        <collision>
            <geometry>
                <mesh filename="file://$(find goddard_description)/meshes/tibia.stl"
                    scale="0.001 0.001 0.001" />
            </geometry>
            <origin xyz="0.01861 0 -0.02100" rpy="0 0 0" />
        </collision>
        <visual>
            <geometry>
                <mesh filename="file://$(find goddard_description)/meshes/tibia.stl"
                    scale="0.001 0.001 0.001" />
            </geometry>
            <origin xyz="0.01861 0 -0.02100" rpy="0 0 0" />
        </visual>
    </link>

    <joint name="back_right_tibia_to_back_right_femur" type="revolute">
        <parent link="back_right_femur" />
        <child link="back_right_tibia" />
        <origin xyz="-0.05367 0 -0.05261" rpy="0 0 0" />
        <axis xyz="0 -1 0" />
        <limit lower="-1.571" upper="1.571" effort="1000" velocity="0.5" />
    </joint>

</robot>